Workbook

Sheet Performance Dashboard
A1: Ticker | B1: Shares Held | C1: Entry Price | D1: Current Price | E1: Total Cost | F1: Market Value | G1: Unrealized Gain/Loss | H1: % Return
A2: NVDA | B2: ='Holdings Sheet'!C13 -> 267 | C2: ='Holdings Sheet'!D13 -> 118.81457 | D2: ='Active Portfolio'!B4 -> 176.75 | E2: =B2*C2 -> 31723.49 | F2: =B2*D2 -> 47192.25 | G2: =F2-E2 -> 15468.76 | H2: =(Table3[[#This Row],[Market Value]]-Table3[[#This Row],[Total Cost]])/Table3[[#This Row],[Total Cost]] -> 0.48761218
A3: NUE | B3: ='Holdings Sheet'!C12 -> 88 | C3: ='Holdings Sheet'!D12 -> 118.81239 | D3: ='Active Portfolio'!B8 -> 144.52 | E3: =B3*C3 -> 10455.49 | F3: =B3*D3 -> 12717.76 | G3: =F3-E3 -> 2262.27 | H3: =(Table3[[#This Row],[Market Value]]-Table3[[#This Row],[Total Cost]])/Table3[[#This Row],[Total Cost]] -> 0.21637149
A4: FSLR | B4: ='Holdings Sheet'!C6 -> 288 | C4: ='Holdings Sheet'!D6 -> 153.1958 | D4: ='Active Portfolio'!B16 -> 183.58 | E4: =B4*C4 -> 44120.39 | F4: =B4*D4 -> 52871.04 | G4: =F4-E4 -> 8750.65 | H4: =(Table3[[#This Row],[Market Value]]-Table3[[#This Row],[Total Cost]])/Table3[[#This Row],[Total Cost]] -> 0.19833574
A5: NFLX | B5: ='Holdings Sheet'!C11 -> 49 | C5: ='Holdings Sheet'!D11 -> 1028.1033 | D5: ='Active Portfolio'!B3 -> 1174.6 | E5: =B5*C5 -> 50377.06 | F5: =B5*D5 -> 57555.4 | G5: =F5-E5 -> 7178.34 | H5: =(Table3[[#This Row],[Market Value]]-Table3[[#This Row],[Total Cost]])/Table3[[#This Row],[Total Cost]] -> 0.14249224
A6: PYPL | B6: ='Holdings Sheet'!C14 -> 199 | C6: ='Holdings Sheet'!D14 -> 69.49598 | D6: ='Active Portfolio'!B18 -> 78.22 | E6: =B6*C6 -> 13829.7 | F6: =B6*D6 -> 15565.78 | G6: =F6-E6 -> 1736.08 | H6: =(Table3[[#This Row],[Market Value]]-Table3[[#This Row],[Total Cost]])/Table3[[#This Row],[Total Cost]] -> 0.12553273
A7: GOOG | B7: ='Holdings Sheet'!C7 -> 297 | C7: ='Holdings Sheet'!D7 -> 173.90966 | D7: ='Active Portfolio'!B5 -> 193.42 | E7: =B7*C7 -> 51651.17 | F7: =B7*D7 -> 57445.74 | G7: =F7-E7 -> 5794.57 | H7: =(Table3[[#This Row],[Market Value]]-Table3[[#This Row],[Total Cost]])/Table3[[#This Row],[Total Cost]] -> 0.11218662
A8: CAT | B8: ='Holdings Sheet'!C5 -> 65 | C8: ='Holdings Sheet'!D5 -> 391.83646 | D8: ='Active Portfolio'!B10 -> 432.94 | E8: =B8*C8 -> 25469.37 | F8: =B8*D8 -> 28141.1 | G8: =F8-E8 -> 2671.73 | H8: =(Table3[[#This Row],[Market Value]]-Table3[[#This Row],[Total Cost]])/Table3[[#This Row],[Total Cost]] -> 0.10489973
A9: QQQ | B9: ='Holdings Sheet'!C15 -> 94 | C9: ='Holdings Sheet'!D15 -> 514.8 | D9: ='Active Portfolio'!B15 -> 568.14 | E9: =B9*C9 -> 48391.2 | F9: =B9*D9 -> 53405.16 | G9: =F9-E9 -> 5013.96 | H9: =(Table3[[#This Row],[Market Value]]-Table3[[#This Row],[Total Cost]])/Table3[[#This Row],[Total Cost]] -> 0.10361305
A10: JPM | B10: ='Holdings Sheet'!C9 -> 251 | C10: ='Holdings Sheet'!D9 -> 271.75514 | D10: ='Active Portfolio'!B6 -> 298.28 | E10: =B10*C10 -> 68210.54 | F10: =B10*D10 -> 74868.28 | G10: =F10-E10 -> 6657.74 | H10: =(Table3[[#This Row],[Market Value]]-Table3[[#This Row],[Total Cost]])/Table3[[#This Row],[Total Cost]] -> 0.097605737
A11: SPY | B11: ='Holdings Sheet'!C16 -> 31 | C11: ='Holdings Sheet'!D16 -> 588.14 | D11: ='Active Portfolio'!B14 -> 636.94 | E11: =B11*C11 -> 18232.34 | F11: =B11*D11 -> 19745.14 | G11: =F11-E11 -> 1512.8 | H11: =(Table3[[#This Row],[Market Value]]-Table3[[#This Row],[Total Cost]])/Table3[[#This Row],[Total Cost]] -> 0.082973442
A12: JNJ | B12: ='Holdings Sheet'!C8 -> 169 | C12: ='Holdings Sheet'!D8 -> 154.76343 | D12: ='Active Portfolio'!B13 -> 166.22 | E12: =B12*C12 -> 26155.02 | F12: =B12*D12 -> 28091.18 | G12: =F12-E12 -> 1936.16 | H12: =(Table3[[#This Row],[Market Value]]-Table3[[#This Row],[Total Cost]])/Table3[[#This Row],[Total Cost]] -> 0.074026325
A13: AMZN | B13: ='Holdings Sheet'!C4 -> 141 | C13: ='Holdings Sheet'!D4 -> 217.51404 | D13: ='Active Portfolio'!B11 -> 232.79 | E13: =B13*C13 -> 30669.48 | F13: =B13*D13 -> 32823.39 | G13: =F13-E13 -> 2153.91 | H13: =(Table3[[#This Row],[Market Value]]-Table3[[#This Row],[Total Cost]])/Table3[[#This Row],[Total Cost]] -> 0.070229753
A14: VXUS | B14: ='Holdings Sheet'!C17 -> 1513 | C14: ='Holdings Sheet'!D17 -> 67.399888 | D14: ='Active Portfolio'!B7 -> 69.57 | E14: =B14*C14 -> 101976.03 | F14: =B14*D14 -> 105259.41 | G14: =F14-E14 -> 3283.38 | H14: =(Table3[[#This Row],[Market Value]]-Table3[[#This Row],[Total Cost]])/Table3[[#This Row],[Total Cost]] -> 0.032197566
A15: MA | B15: ='Holdings Sheet'!C20 -> 20 | C15: ='Holdings Sheet'!D20 -> 557.82 | D15: ='Active Portfolio'!B20 -> 568.28 | E15: =B15*C15 -> 11156.4 | F15: =B15*D15 -> 11365.6 | G15: =F15-E15 -> 209.2 | H15: =(Table3[[#This Row],[Market Value]]-Table3[[#This Row],[Total Cost]])/Table3[[#This Row],[Total Cost]] -> 0.018751569
A16: XOM | B16: ='Holdings Sheet'!C18 -> 174 | C16: ='Holdings Sheet'!D18 -> 109.70448 | D16: ='Active Portfolio'!B9 -> 111.44 | E16: =B16*C16 -> 19088.58 | F16: =B16*D16 -> 19390.56 | G16: =F16-E16 -> 301.98 | H16: =(Table3[[#This Row],[Market Value]]-Table3[[#This Row],[Total Cost]])/Table3[[#This Row],[Total Cost]] -> 0.01581993
A17: LNG | B17: ='Holdings Sheet'!C10 -> 236 | C17: ='Holdings Sheet'!D10 -> 225.86051 | D17: ='Active Portfolio'!B17 -> 228.48 | E17: =B17*C17 -> 53303.08 | F17: =B17*D17 -> 53921.28 | G17: =F17-E17 -> 618.2 | H17: =(Table3[[#This Row],[Market Value]]-Table3[[#This Row],[Total Cost]])/Table3[[#This Row],[Total Cost]] -> 0.011597829
A18: AAPL | B18: ='Holdings Sheet'!C3 -> 147 | C18: ='Holdings Sheet'!D3 -> 212.11918 | D18: ='Active Portfolio'!B12 -> 214.05 | E18: =B18*C18 -> 31181.52 | F18: =B18*D18 -> 31465.35 | G18: =F18-E18 -> 283.83 | H18: =(Table3[[#This Row],[Market Value]]-Table3[[#This Row],[Total Cost]])/Table3[[#This Row],[Total Cost]] -> 0.0091025069
A19: V | B19: ='Holdings Sheet'!C21 -> 32 | C19: ='Holdings Sheet'!D21 -> 353 | D19: ='Active Portfolio'!B21 -> 355.47 | E19: =B19*C19 -> 11296 | F19: =B19*D19 -> 11375.04 | G19: =F19-E19 -> 79.04 | H19: =(Table3[[#This Row],[Market Value]]-Table3[[#This Row],[Total Cost]])/Table3[[#This Row],[Total Cost]] -> 0.0069971671
A20: VDC | B20: ='Holdings Sheet'!C19 -> 190 | C20: ='Holdings Sheet'!D19 -> 216.99 | D20: ='Active Portfolio'!B19 -> 218.27 | E20: =B20*C20 -> 41228.1 | F20: =B20*D20 -> 41471.3 | G20: =F20-E20 -> 243.2 | H20: =(Table3[[#This Row],[Market Value]]-Table3[[#This Row],[Total Cost]])/Table3[[#This Row],[Total Cost]] -> 0.0058988893
A21: Total | B21: =SUBTOTAL(109,Table3[Shares Held]) -> 4251 | E21: =SUBTOTAL(109,Table3[Total Cost]) -> 688514.96 | F21: =SUBTOTAL(109,Table3[Market Value]) -> 754670.76 | G21: =Table3[[#Totals],[Market Value]]/Table3[[#Totals],[Total Cost]]-1 -> 0.096084768 | H21: =SUBTOTAL(109,Table3[% Return]) -> 1.9162445

Sheet Summary Dashboard
A1: Metric | B1: Value
A2: As of Date | B2: =TODAY() -> 45866
A3: Total Portfolio Value | B3: 1065952.4
A4: Total Cash Available | B4: 363102.99
A5: Invested Amount | B5: =B3-B4 -> 702849.43
A6: Total Holdings
A7: Top Allocation | B7: =INDEX('Holdings Sheet'!A3:A21,MATCH(MAX('Holdings Sheet'!G3:G21),'Holdings Sheet'!G3:G21,0)) & "-" & TEXT(MAX('Holdings Sheet'!G3:G21), "0.00%") -> VXUS-9.87%
A8: Lowest Allocation | B8: =INDEX('Holdings Sheet'!A3:A21,MATCH(MIN('Holdings Sheet'!G3:G21), 'Holdings Sheet'!G3:G21,0)) & "-" & TEXT(MIN('Holdings Sheet'!G3:G21),"0.00%") -> MA-1.07%
A9: Average Allocation | B9: =AVERAGE('Holdings Sheet'!G7) -> 0.053891467
A10: Cash Allocation | B10: ='Holdings Sheet'!F18 /B3 -> 0.018190831
A11: Total Estimated Annual Dividends | B11: 1456.57
A13: Other Assets
A14: Bonds | B14: 3121.49
A15: Crypto | B15: 13720.7
A16: Total Other Assets | B16: =SUM(B14:B15) -> 16842.19

Sheet Active Portfolio
A1: Stock Purchased | B1: Stock Not Purchased
B2: Price | C2: 52 Wk Hgh | D2: 52 Wk Low | E2: Volume | F2: Previous Close | G2: Alert 1 | H2: Alert 2 | I2: Alert 3 | J2: Alert 4 | K2: Alert 5 | M2: Breakout= Buy
A3: #VALUE! | B3: {=_FV(A3,"Price")} -> 1174.6 | C3: {=_FV(A3,"52 week high",TRUE)} -> 1341.15 | D3: {=_FV(A3,"52 week low",TRUE)} -> 587.04 | E3: {=_FV(A3,"Volume")} -> 3446958 | F3: {=_FV(A3,"Previous close",TRUE)} -> 1180.49 | G3: =IF(B3>=1240,"New 52W High Breakout","") | H3: =IF(AND(B3>=1200,B3<=1235),"Pullback Opportunity","") | I3: =IF(AND(B3>=1150,B3<1200),"Test of Trailing Stop Zone","") -> Test of Trailing Stop Zone | J3: =IF(B3<=1149,"Triggered Stop Loss Zone","") | M3: Price Dip- Buy
A4: #VALUE! | B4: {=_FV(A4,"Price")} -> 176.75 | C4: {=_FV(A4,"52 week high",TRUE)} -> 177 | D4: {=_FV(A4,"52 week low",TRUE)} -> 86.62 | E4: {=_FV(A4,"Volume")} -> 140023521 | F4: {=_FV(A4,"Previous close",TRUE)} -> 173.5 | G4: =IF(AND(B4>=165, B4<=166.32), "Breakout!", " ") | H4: =IF(B4>=166.33, "Trim Alert", " ") -> Trim Alert | I4: =IF(AND(B4<=155,B4>=145), "Dip Buy Opportunity", "") | J4: =IF(B4<=156.63, "Stop Loss Trigger", "") | M4: Sell
A5: #VALUE! | B5: {=_FV(A5,"Price")} -> 193.42 | C5: {=_FV(A5,"52 week high",TRUE)} -> 208.7 | D5: {=_FV(A5,"52 week low",TRUE)} -> 142.66 | E5: {=_FV(A5,"Volume")} -> 25553546 | F5: {=_FV(A5,"Previous close",TRUE)} -> 194.08 | G5: =IF(B5>=182, "Watch for Breakout Zone", " ") -> Watch for Breakout Zone | H5: =IF(AND(B5<=168, B5>=162), "Dip Buy Opportunit", " ") | J5: =IF(B5<=164.4, "Stop Loss Trigger", "")
A6: #VALUE! | B6: {=_FV(A6,"Price")} -> 298.28 | C6: {=_FV(A6,"52 week high",TRUE)} -> 299.5899 | D6: {=_FV(A6,"52 week low",TRUE)} -> 190.9 | E6: {=_FV(A6,"Volume")} -> 5840417 | F6: {=_FV(A6,"Previous close",TRUE)} -> 298.62 | G6: =IF(B6>=285, "Breakout Zone") -> Breakout Zone | H6: =IF(B6>=ROUND(271.76*1.1,2), "Trim Opportunity / Near Target"," ") | I6: =IF(AND(B6<=265,B6>=255), "Early Dip Zone", " ") | J6: =IF(B6<=245, "Approaching 200MA Support", " ")
A7: #VALUE! | B7: {=_FV(A7,"Price")} -> 69.57 | C7: {=_FV(A7,"52 week high",TRUE)} -> 71.08 | D7: {=_FV(A7,"52 week low",TRUE)} -> 54.98 | E7: {=_FV(A7,"Volume")} -> 4951468 | F7: {=_FV(A7,"Previous close",TRUE)} -> 70.48 | G7: =IF(B7>=ROUND(67.4*1.1,2), "Profit Target Reached – Review Trim", "") | H7: =IF(AND(B7>=67,B7<=68.24), "Breakout Confirmation Zone", "") | I7: =IF(AND(B7<=65.5,B7>=63),"First Dip Buying Oppt", " ") | J7: =IF(AND(C7<=63,C7>=61.26),"Second Dip Zone, Aggresive", " ") | K7: =IF(B7<=61.25, "Reevaluate Position", " ")
A8: #VALUE! | B8: {=_FV(A8,"Price")} -> 144.52 | C8: {=_FV(A8,"52 week high",TRUE)} -> 170.52 | D8: {=_FV(A8,"52 week low",TRUE)} -> 97.59 | E8: {=_FV(A8,"Volume")} -> 2404202 | F8: {=_FV(A8,"Previous close",TRUE)} -> 145.83 | G8: =IF(B8>F8, "Above Previous Closed", " ") | H8: =IF(B8>=132.03, " 200MA Breakout Confirmed", " ") -> 200MA Breakout Confirmed | I8: =IF(B8>=ROUND(118.81*1.3,2), "Trim Zone – 30% Return", "") | J8: =IF(B8<=133, "Trigger Stop Loss", " ")
A9: #VALUE! | B9: {=_FV(A9,"Price")} -> 111.44 | C9: {=_FV(A9,"52 week high",TRUE)} -> 126.34 | D9: {=_FV(A9,"52 week low",TRUE)} -> 97.8 | E9: {=_FV(A9,"Volume")} -> 12352966 | F9: {=_FV(A9,"Previous close",TRUE)} -> 110.4 | G9: =IF(B9>=108.1, "📈 Breakout Watch", "") -> 📈 Breakout Watch | H9: =IF(B9>=116.5, "🚀 Breakout Confirmation Zone", "") | I9: =IF(B9>=122, "🎯 Target Profit Zone (Trim Consideration)", "") | J9: =IF(B9<=103.13, "Trigger Stop Loss", " ")
A10: #VALUE! | B10: {=_FV(A10,"Price")} -> 432.94 | C10: {=_FV(A10,"52 week high",TRUE)} -> 436.4 | D10: {=_FV(A10,"52 week low",TRUE)} -> 267.3 | E10: {=_FV(A10,"Volume")} -> 2550479 | F10: {=_FV(A10,"Previous close",TRUE)} -> 433.75 | G10: =IF(B10>=355.15, "🚨 Broke 200 MA Resistance", "") -> 🚨 Broke 200 MA Resistance | H10: =IF(B10>=328.56, "📈 Strong Momentum", "") -> 📈 Strong Momentum | I10: =IF(B10>=462, "💰Trim Alert 18% Profit", "") | J10: =IF(B10<=382.78, "⚠️ Trigger Stop Loss", "")
A11: #VALUE! | B11: {=_FV(A11,"Price")} -> 232.79 | C11: {=_FV(A11,"52 week high",TRUE)} -> 242.52 | D11: {=_FV(A11,"52 week low",TRUE)} -> 151.61 | E11: {=_FV(A11,"Volume")} -> 26300138 | F11: {=_FV(A11,"Previous close",TRUE)} -> 231.44 | G11: =IF(B11>=225, "🚀 Breakout Holding – Bullish", "") -> 🚀 Breakout Holding – Bullish | H11: =IF(B11>=238, "📌 10% Profit Alert – Review for Trim", "") | I11: =IF(B11<=215, "⚠️ Below EMA20 – Caution Zone", "")
A12: #VALUE! | B12: {=_FV(A12,"Price")} -> 214.05 | C12: {=_FV(A12,"52 week high",TRUE)} -> 260.1 | D12: {=_FV(A12,"52 week low",TRUE)} -> 169.2101 | E12: {=_FV(A12,"Volume")} -> 37858017 | F12: {=_FV(A12,"Previous close",TRUE)} -> 213.88 | G12: =IF(AND(B12>=206.47,B12<=207.6), "📈 Bullish Short-Term", "") | H12: =IF(B12>=207.61, "🚀 Watch for Breakout", "") -> 🚀 Watch for Breakout | I12: =IF(B12<=206, "⚠️ Pullback Watch", "")
A13: #VALUE! | B13: {=_FV(A13,"Price")} -> 166.22 | C13: {=_FV(A13,"52 week high",TRUE)} -> 169.99 | D13: {=_FV(A13,"52 week low",TRUE)} -> 140.68 | E13: {=_FV(A13,"Volume")} -> 8014640 | F13: {=_FV(A13,"Previous close",TRUE)} -> 168.3 | G13: =IF(B13<=152.04, "❌ Bearish Setup Below all MAs", "") | H13: =IF(AND(B13>152.04, B13<154), "👀 Watch for Reversal", "") | I13: =IF(B13>=156.5, "🚀 Breakout Watch (Above 50 MA)Buy Opportunity", "") -> 🚀 Breakout Watch (Above 50 MA)Buy Opportunity | J13: =IF(B13>158, " Breakout Confirmation, Buy 25%", " ") -> Breakout Confirmation, Buy 25% | K13: =IF(B13>=ROUND(C13*1.1,2),"10% Target Reached – Review for Trim", " ")
A14: #VALUE! | B14: {=_FV(A14,"Price")} -> 636.94 | C14: {=_FV(A14,"52 week high",TRUE)} -> 638.04 | D14: {=_FV(A14,"52 week low",TRUE)} -> 481.8 | E14: {=_FV(A14,"Volume")} -> 54917102 | F14: {=_FV(A14,"Previous close",TRUE)} -> 637.1 | G14: =IF(B14>=605, "📈 New Breakout Zone- Confirmed Strength", " ") -> 📈 New Breakout Zone- Confirmed Strength | H14: =IF(B14<=614, "⚠️ Caution: Pullback from EMA20", "") | I14: =IF(B14>=646, "🚨 Overbought Watch – Review for Trim", "")
A15: #VALUE! | B15: {=_FV(A15,"Price")} -> 568.14 | C15: {=_FV(A15,"52 week high",TRUE)} -> 569.04 | D15: {=_FV(A15,"52 week low",TRUE)} -> 402.39 | E15: {=_FV(A15,"Volume")} -> 31498739 | F15: {=_FV(A15,"Previous close",TRUE)} -> 566.37 | G15: =IF(B15>=560, "📈 Breakout Zone – Consider Trim Near $570", "") -> 📈 Breakout Zone – Consider Trim Near $570 | H15: =IF(AND(B15<=545,B15>=525), "🟡 Healthy Pullback Entry Zone", "") | I15: =IF(B15>=590, "10% Gains, Trim Profits", " ") | J15: =IF(B15<=528,"Trigger Stop Loss", " ")
A16: #VALUE! | B16: {=_FV(A16,"Price")} -> 183.58 | C16: {=_FV(A16,"52 week high",TRUE)} -> 262.72 | D16: {=_FV(A16,"52 week low",TRUE)} -> 116.5625 | E16: {=_FV(A16,"Volume")} -> 2622123 | F16: {=_FV(A16,"Previous close",TRUE)} -> 185.32 | G16: =IF(B16>=165, "Momentum", " ") -> Momentum | H16: =IF(B16>=ROUND(153.2*1.3,2), "Trim Zone – 30% Return", "") | I16: =IF(AND(B16>=162, B16<=165), "Caution, Pullback, Buy Target Allocation", " ") | J16: =IF(B16<=155, "Near Stop Loss", " ")
A17: #VALUE! | B17: {=_FV(A17,"Price")} -> 228.48 | C17: {=_FV(A17,"52 week high",TRUE)} -> 257.65 | D17: {=_FV(A17,"52 week low",TRUE)} -> 167.6632 | E17: {=_FV(A17,"Volume")} -> 2798336 | F17: {=_FV(A17,"Previous close",TRUE)} -> 225.37 | G17: =IF(AND(B17>=240,B17<=249.99), "Breakout", " ") | H17: =IF(B17>=ROUND(230*1.1, 2), "10% Trim Profits", " ")
A18: #VALUE! | B18: {=_FV(A18,"Price")} -> 78.22 | C18: {=_FV(A18,"52 week high",TRUE)} -> 93.66 | D18: {=_FV(A18,"52 week low",TRUE)} -> 55.85 | E18: {=_FV(A18,"Volume")} -> 15978415 | F18: {=_FV(A18,"Previous close",TRUE)} -> 77.98 | G18: =IF(AND(B18>=68, B18<=75), "Reversal Watch, (Holding 20-EMA)", " ") | H18: =IF(B18>76.5, "Breakout", " ") -> Breakout | I18: =IF(B18<68, "Breakdown", " ")
A19: #VALUE! | B19: {=_FV(A19,"Price")} -> 218.27 | C19: {=_FV(A19,"52 week high",TRUE)} -> 226.64 | D19: {=_FV(A19,"52 week low",TRUE)} -> 202.955 | E19: {=_FV(A19,"Volume")} -> 96034 | F19: {=_FV(A19,"Previous close",TRUE)} -> 220.14 | G19: =IF(B19>=219, "Above ALL MA's Breakout", " ") | H19: =IF(AND(B19<218.7, B19>=214.02), "Price Dip, Buy Opportunity", " ") -> Price Dip, Buy Opportunity | I19: =IF(B19<=213, "Trend Reversal, Stop loss", " ")
A20: #VALUE! | B20: {=_FV(A20,"Price")} -> 568.28 | C20: {=_FV(A20,"52 week high",TRUE)} -> 594.71 | D20: {=_FV(A20,"Low")} -> 566.22 | E20: {=_FV(A20,"Volume")} -> 2492411 | F20: {=_FV(A20,"Previous close",TRUE)} -> 568.22 | G20: =IF(AND(B20>=566.98, B20<=569.99),"Minor Breakout Above 50MA, Consider buy", " ") -> Minor Breakout Above 50MA, Consider buy | H20: =IF(B20>=575, "Breakout Above 570, Buy Opportunity", " ") | I20: =IF(B20>=613.6, "10% Gains, Consider Trimming", " ")
A21: #VALUE! | B21: {=_FV(A21,"Price")} -> 355.47 | C21: {=_FV(A21,"52 week high",TRUE)} -> 375.51 | D21: {=_FV(A21,"52 week low",TRUE)} -> 254.51 | E21: {=_FV(A21,"Volume")} -> 3920959 | F21: {=_FV(A21,"Previous close",TRUE)} -> 357.04 | G21: =IF(AND(B21>=357,B21<=356.99), "Minor Breakout 50MA+, Consider buying", " ") | H21: =IF(B21>=375, "Major Breakout, Buy Oppt", " ") | I21: =IF(B21>=388.3, "10% Gains, Consider Trimming", " ") | J21: =IF(B21<=330.16,"Trigger Stop Loss", " ")

Sheet Rebalance Sheet
A1: Portfolio Value | B1: ='Holdings Sheet'!F24 -> 1065952.4
B2: CURRENT | C2: TARGET | D2: REMAINING | E2: ALLOCATION | F2: PORTFOLIO | G2: TARGET $ | H2: CURRENT $ | I2: REBALANCE | K2: TRANCHE | L2: TRENCH | M2: CURRENT | N2: SHARES
A3: TICKER | B3: ALLOCATION % | C3: ALLOCATION % | D3: ALLOCATION | E3: ALERT | F3: VALUE | G3: AMOUNT | H3: AMOUNT | I3: AMOUNT | J3: ACTION | K3: GROUP | L3: DATE | M3: PRICE | N3: BUY/SALE
A4: AAPL | B4: ='Holdings Sheet'!G3 -> 0.029518531 | C4: =B4 -> 0.029518531 | D4: =C4-B4 -> 0 | E4: =IF(B4<C4, "⬆ Add", IF(B4>C4, "⬇ Trim", "✅ Target Met")) -> ✅ Target Met | F4: =$B$1 -> 1065952.4 | G4: =C4*F4 -> 31465.35 | H4: ='Holdings Sheet'!F3 -> 31465.35 | I4: =G4-H4 -> 0 | J4: =IF(I4>0, "Buy", IF(I4<0, "Sell", "Hold")) -> Hold | K4: Trenche 1 | L4: 45795 | M4: ='Holdings Sheet'!E3 -> 214.05 | N4: =I4/M4 -> 0
A5: AMZN | B5: ='Holdings Sheet'!G4 -> 0.030792547 | C5: =B5 -> 0.030792547 | D5: =C5-B5 -> 0 | E5: =IF(B5<C5, "⬆ Add", IF(B5>C5, "⬇ Trim", "✅ Target Met")) -> ✅ Target Met | F5: =$B$1 -> 1065952.4 | G5: =C5*F5 -> 32823.39 | H5: ='Holdings Sheet'!F4 -> 32823.39 | I5: =G5-H5 -> 0 | J5: =IF(I5>0, "Buy", IF(I5<0, "Sell", "Hold")) -> Hold | K5: Trenche 2 | L5: 45817 | M5: ='Holdings Sheet'!E4 -> 232.79 | N5: =I5/M5 -> 0
A6: CAT | B6: ='Holdings Sheet'!G5 -> 0.026399959 | C6: =B6 -> 0.026399959 | D6: =C6-B6 -> 0 | E6: =IF(B6<C6, "⬆ Add", IF(B6>C6, "⬇ Trim", "✅ Target Met")) -> ✅ Target Met | F6: =$B$1 -> 1065952.4 | G6: =C6*F6 -> 28141.1 | H6: ='Holdings Sheet'!F5 -> 28141.1 | I6: =G6-H6 -> 0 | J6: =IF(I6>0, "Buy", IF(I6<0, "Sell", "Hold")) -> Hold | K6: Trenche 1 | L6: 45795 | M6: ='Holdings Sheet'!E5 -> 432.94 | N6: =I6/M6 -> 0
A7: FSLR | B7: ='Holdings Sheet'!G6 -> 0.049599812 | C7: =B7 -> 0.049599812 | D7: =C7-B7 -> 0 | E7: =IF(B7<C7, "⬆ Add", IF(B7>C7, "⬇ Trim", "✅ Target Met")) -> ✅ Target Met | F7: =$B$1 -> 1065952.4 | G7: =C7*F7 -> 52871.04 | H7: ='Holdings Sheet'!F6 -> 52871.04 | I7: =G7-H7 -> 0 | J7: =IF(I7>0, "Buy", IF(I7<0, "Sell", "Hold")) -> Hold | K7: Trench 3 | L7: 45855 | M7: ='Holdings Sheet'!E6 -> 183.58 | N7: =I7/M7 -> 0
A8: GOOG | B8: ='Holdings Sheet'!G7 -> 0.053891467 | C8: 0.06 | D8: =C8-B8 -> 0.0061085327 | E8: =IF(B8<C8, "⬆ Add", IF(B8>C8, "⬇ Trim", "✅ Target Met")) -> ⬆ Add | F8: =$B$1 -> 1065952.4 | G8: =C8*F8 -> 63957.145 | H8: ='Holdings Sheet'!F7 -> 57445.74 | I8: =G8-H8 -> 6511.4052 | J8: =IF(I8>0, "Buy", IF(I8<0, "Sell", "Hold")) -> Buy | K8: Trench 1 | L8: 45855 | M8: ='Holdings Sheet'!E7 -> 193.42 | N8: =I8/M8 -> 33.664591
A9: JNJ | B9: ='Holdings Sheet'!G8 -> 0.026353127 | C9: =B9 -> 0.026353127 | D9: =C9-B9 -> 0 | E9: =IF(B9<C9, "⬆ Add", IF(B9>C9, "⬇ Trim", "✅ Target Met")) -> ✅ Target Met | F9: =$B$1 -> 1065952.4 | G9: =C9*F9 -> 28091.18 | H9: ='Holdings Sheet'!F8 -> 28091.18 | I9: =G9-H9 -> 0 | J9: =IF(I9>0, "Buy", IF(I9<0, "Sell", "Hold")) -> Hold | K9: Trenche 2 | L9: 45810 | M9: ='Holdings Sheet'!E8 -> 166.22 | N9: =I9/M9 -> 0
A10: JPM | B10: ='Holdings Sheet'!G9 -> 0.070236043 | C10: =B10 -> 0.070236043 | D10: =C10-B10 -> 0 | E10: =IF(B10<C10, "⬆ Add", IF(B10>C10, "⬇ Trim", "✅ Target Met")) -> ✅ Target Met | F10: =$B$1 -> 1065952.4 | G10: =C10*F10 -> 74868.28 | H10: ='Holdings Sheet'!F9 -> 74868.28 | I10: =G10-H10 -> 0 | J10: =IF(I10>0, "Buy", IF(I10<0, "Sell", "Hold")) -> Hold | K10: N/A | L10: N/A | M10: ='Holdings Sheet'!E9 -> 298.28 | N10: =I10/M10 -> 0
A11: LNG | B11: ='Holdings Sheet'!G10 -> 0.050585072 | C11: 0.05 | D11: =C11-B11 -> -0.00058507208 | E11: =IF(B11<C11, "⬆ Add", IF(B11>C11, "⬇ Trim", "✅ Target Met")) -> ⬇ Trim | F11: =$B$1 -> 1065952.4 | G11: =C11*F11 -> 53297.621 | H11: ='Holdings Sheet'!F10 -> 53921.28 | I11: =G11-H11 -> -623.659 | J11: =IF(I11>0, "Buy", IF(I11<0, "Sell", "Hold")) -> Sell | K11: Trench 1 | L11: 45806 | M11: ='Holdings Sheet'!E10 -> 228.48 | N11: =I11/M11 -> -2.7296
A12: NFLX | B12: ='Holdings Sheet'!G11 -> 0.053994342 | C12: 0.07 | D12: =C12-B12 -> 0.016005658 | E12: =IF(B12<C12, "⬆ Add", IF(B12>C12, "⬇ Trim", "✅ Target Met")) -> ⬆ Add | F12: =$B$1 -> 1065952.4 | G12: =C12*F12 -> 74616.669 | H12: ='Holdings Sheet'!F11 -> 57555.4 | I12: =G12-H12 -> 17061.269 | J12: =IF(I12>0, "Buy", IF(I12<0, "Sell", "Hold")) -> Buy | K12: N/A | L12: N/A | M12: ='Holdings Sheet'!E11 -> 1174.6 | N12: =I12/M12 -> 14.525174
A13: NUE | B13: ='Holdings Sheet'!G12 -> 0.011930889 | C13: 0.05 | D13: =C13-B13 -> 0.038069111 | E13: =IF(B13<C13, "⬆ Add", IF(B13>C13, "⬇ Trim", "✅ Target Met")) -> ⬆ Add | F13: =$B$1 -> 1065952.4 | G13: =C13*F13 -> 53297.621 | H13: ='Holdings Sheet'!F12 -> 12717.76 | I13: =G13-H13 -> 40579.861 | J13: =IF(I13>0, "Buy", IF(I13<0, "Sell", "Hold")) -> Buy | K13: Trenche 1 | L13: 45812 | M13: ='Holdings Sheet'!E12 -> 144.52 | N13: =I13/M13 -> 280.79062
A14: NVDA | B14: ='Holdings Sheet'!G13 -> 0.044272379 | C14: 0.1 | D14: =C14-B14 -> 0.055727621 | E14: =IF(B14<C14, "⬆ Add", IF(B14>C14, "⬇ Trim", "✅ Target Met")) -> ⬆ Add | F14: =$B$1 -> 1065952.4 | G14: =C14*F14 -> 106595.24 | H14: ='Holdings Sheet'!F13 -> 47192.25 | I14: =G14-H14 -> 59402.992 | J14: =IF(I14>0, "Buy", IF(I14<0, "Sell", "Hold")) -> Buy | K14: N/A | L14: N/A | M14: ='Holdings Sheet'!E13 -> 176.75 | N14: =I14/M14 -> 336.08482
A15: PYPL | B15: ='Holdings Sheet'!G14 -> 0.014602697 | C15: =B15 -> 0.014602697 | D15: =C15-B15 -> 0 | E15: =IF(B15<C15, "⬆ Add", IF(B15>C15, "⬇ Trim", "✅ Target Met")) -> ✅ Target Met | F15: =$B$1 -> 1065952.4 | G15: =C15*F15 -> 15565.78 | H15: ='Holdings Sheet'!F14 -> 15565.78 | I15: =G15-H15 -> 0 | J15: =IF(I15>0, "Buy", IF(I15<0, "Sell", "Hold")) -> Hold | K15: Trenche 1 | L15: 45808 | M15: ='Holdings Sheet'!E14 -> 78.22 | N15: =I15/M15 -> 0
A16: QQQ | B16: ='Holdings Sheet'!G15 -> 0.050100885 | C16: =B16 -> 0.050100885 | D16: =C16-B16 -> 0 | E16: =IF(B16<C16, "⬆ Add", IF(B16>C16, "⬇ Trim", "✅ Target Met")) -> ✅ Target Met | F16: =$B$1 -> 1065952.4 | G16: =C16*F16 -> 53405.16 | H16: ='Holdings Sheet'!F15 -> 53405.16 | I16: =G16-H16 -> 0 | J16: =IF(I16>0, "Buy", IF(I16<0, "Sell", "Hold")) -> Hold | K16: Trenche 2 | L16: 45815 | M16: ='Holdings Sheet'!E15 -> 568.14 | N16: =I16/M16 -> 0
A17: SPY | B17: ='Holdings Sheet'!G16 -> 0.018523472 | C17: 0.05 | D17: =C17-B17 -> 0.031476528 | E17: =IF(B17<C17, "⬆ Add", IF(B17>C17, "⬇ Trim", "✅ Target Met")) -> ⬆ Add | F17: =$B$1 -> 1065952.4 | G17: =C17*F17 -> 53297.621 | H17: ='Holdings Sheet'!F16 -> 19745.14 | I17: =G17-H17 -> 33552.481 | J17: =IF(I17>0, "Buy", IF(I17<0, "Sell", "Hold")) -> Buy | K17: Trenche 1 | L17: 45795 | M17: ='Holdings Sheet'!E16 -> 636.94 | N17: =I17/M17 -> 52.677616
A18: VXUS | B18: ='Holdings Sheet'!G17 -> 0.098746818 | C18: =B18 -> 0.098746818 | D18: =C18-B18 -> 0 | E18: =IF(B18<C18, "⬆ Add", IF(B18>C18, "⬇ Trim", "✅ Target Met")) -> ✅ Target Met | F18: =$B$1 -> 1065952.4 | G18: =C18*F18 -> 105259.41 | H18: ='Holdings Sheet'!F17 -> 105259.41 | I18: =G18-H18 -> 0 | J18: =IF(I18>0, "Buy", IF(I18<0, "Sell", "Hold")) -> Hold | K18: N/A | L18: N/A | M18: ='Holdings Sheet'!E17 -> 69.57 | N18: =I18/M18 -> 0
A19: XOM | B19: ='Holdings Sheet'!G18 -> 0.018190831 | C19: =B19 -> 0.018190831 | D19: =C19-B19 -> 0 | E19: =IF(B19<C19, "⬆ Add", IF(B19>C19, "⬇ Trim", "✅ Target Met")) -> ✅ Target Met | F19: =$B$1 -> 1065952.4 | G19: =C19*F19 -> 19390.56 | H19: ='Holdings Sheet'!F18 -> 19390.56 | I19: =G19-H19 -> 0 | J19: =IF(I19>0, "Buy", IF(I19<0, "Sell", "Hold")) -> Hold | K19: Trenche 2 | L19: 45824 | M19: ='Holdings Sheet'!E18 -> 111.44 | N19: =I19/M19 -> 0
A20: VDC | B20: ='Holdings Sheet'!G19 -> 0.038905395 | C20: =B20 -> 0.038905395 | D20: =C20-B20 -> 0 | E20: =IF(B20<C20, "⬆ Add", IF(B20>C20, "⬇ Trim", "✅ Target Met")) -> ✅ Target Met | F20: =$B$1 -> 1065952.4 | G20: =C20*F20 -> 41471.3 | H20: ='Holdings Sheet'!F19 -> 41471.3 | I20: =G20-H20 -> 0 | J20: =IF(I20>0, "Buy", IF(I20<0, "Sell", "Hold")) -> Hold | K20: Trench 1 | L20: 45834 | M20: ='Holdings Sheet'!E19 -> 218.27 | N20: =I20/M20 -> 0
A21: MA | B21: ='Holdings Sheet'!G20 -> 0.01066239 | C21: 0.02 | D21: =C21-B21 -> 0.0093376104 | E21: =IF(B21<C21, "⬆ Add", IF(B21>C21, "⬇ Trim", "✅ Target Met")) -> ⬆ Add | F21: =$B$1 -> 1065952.4 | G21: =C21*F21 -> 21319.048 | H21: ='Holdings Sheet'!F20 -> 11365.6 | I21: =G21-H21 -> 9953.4484 | J21: =IF(I21>0, "Buy", IF(I21<0, "Sell", "Hold")) -> Buy | K21: Trench 1 | L21: 45860 | M21: ='Holdings Sheet'!E20 -> 568.28 | N21: =I21/M21 -> 17.515043
A22: V | B22: ='Holdings Sheet'!G21 -> 0.010671246 | C22: 0.02 | D22: =C22-B22 -> 0.0093287545 | E22: =IF(B22<C22, "⬆ Add", IF(B22>C22, "⬇ Trim", "✅ Target Met")) -> ⬆ Add | F22: =$B$1 -> 1065952.4 | G22: =C22*F22 -> 21319.048 | H22: ='Holdings Sheet'!F21 -> 11375.04 | I22: =G22-H22 -> 9944.0084 | J22: =IF(I22>0, "Buy", IF(I22<0, "Sell", "Hold")) -> Buy | K22: Trench 2 | L22: 45861 | M22: ='Holdings Sheet'!E21 -> 355.47 | N22: =I22/M22 -> 27.974255

Sheet Holdings Sheet
A1: As of | C1: =TODAY() -> 45866
A2: Ticker | B2: Sector | C2: Shares | D2: Entry Price/Avg Share | E2: Current Price | F2: Market Value | G2: Allocatoin % | H2: Cost Basis | I2: Gain/Loss | J2: % Return | K2: 52W High | L2: % from 52W High | M2: Breakout Watch | N2: 52W Low
A3: AAPL | B3: Technology | C3: ='Transaction Sheet'!D65 -> 147 | D3: ='Transaction Sheet'!D66 -> 212.11918 | E3: ='Active Portfolio'!B12 -> 214.05 | F3: =E3*C3 -> 31465.35 | G3: =F3/$F$24 -> 0.029518531 | H3: =D3*C3 -> 31181.52 | I3: =F3-H3 -> 283.83 | J3: =(I3/H3) -> 0.0091025069 | K3: ='Active Portfolio'!C12 -> 260.1 | L3: =(E3-K3)/K3 -> -0.17704729 | M3: =IF(L3>=-0.03, "🚀 Breakout Watch", "") | N3: ='Active Portfolio'!D12 -> 169.2101
A4: AMZN | B4: Technology | C4: ='Transaction Sheet'!D60 -> 141 | D4: ='Transaction Sheet'!D61 -> 217.51404 | E4: ='Active Portfolio'!B11 -> 232.79 | F4: =E4*C4 -> 32823.39 | G4: =F4/$F$24 -> 0.030792547 | H4: =D4*C4 -> 30669.48 | I4: =F4-H4 -> 2153.91 | J4: =(I4/H4) -> 0.070229753 | K4: ='Active Portfolio'!C11 -> 242.52 | L4: =(E4-K4)/K4 -> -0.040120402 | M4: =IF(L4>=-0.03, "🚀 Breakout Watch", "") | N4: ='Active Portfolio'!D11 -> 151.61
A5: CAT | B5: Industrials | C5: ='Transaction Sheet'!D54 -> 65 | D5: ='Transaction Sheet'!D55 -> 391.83646 | E5: ='Active Portfolio'!B10 -> 432.94 | F5: =E5*C5 -> 28141.1 | G5: =F5/$F$24 -> 0.026399959 | H5: =D5*C5 -> 25469.37 | I5: =F5-H5 -> 2671.73 | J5: =(I5/H5) -> 0.10489973 | K5: ='Active Portfolio'!C10 -> 436.4 | L5: =(E5-K5)/K5 -> -0.007928506 | M5: =IF(L5>=-0.03, "🚀 Breakout Watch", "") -> 🚀 Breakout Watch | N5: ='Active Portfolio'!D10 -> 267.3
A6: FSLR | B6: Industrials | C6: ='Transaction Sheet'!D94 -> 288 | D6: ='Transaction Sheet'!D95 -> 153.1958 | E6: ='Active Portfolio'!B16 -> 183.58 | F6: =E6*C6 -> 52871.04 | G6: =F6/$F$24 -> 0.049599812 | H6: =D6*C6 -> 44120.39 | I6: =F6-H6 -> 8750.65 | J6: =(I6/H6) -> 0.19833574 | K6: ='Active Portfolio'!C16 -> 262.72 | L6: =(E6-K6)/K6 -> -0.30123325 | M6: =IF(L6>=-0.03, "🚀 Breakout Watch", "") | N6: ='Active Portfolio'!D16 -> 116.5625
A7: GOOG | B7: Technology | C7: ='Transaction Sheet'!D17 -> 297 | D7: ='Transaction Sheet'!D18 -> 173.90966 | E7: ='Active Portfolio'!B5 -> 193.42 | F7: =E7*C7 -> 57445.74 | G7: =F7/$F$24 -> 0.053891467 | H7: =D7*C7 -> 51651.17 | I7: =F7-H7 -> 5794.57 | J7: =(I7/H7) -> 0.11218662 | K7: ='Active Portfolio'!C5 -> 208.7 | L7: =(E7-K7)/K7 -> -0.073215141 | M7: =IF(L7>=-0.03, "🚀 Breakout Watch", "") | N7: ='Active Portfolio'!D5 -> 142.66
A8: JNJ | B8: Health Care | C8: ='Transaction Sheet'!D71 -> 169 | D8: ='Transaction Sheet'!D72 -> 154.76343 | E8: ='Active Portfolio'!B13 -> 166.22 | F8: =E8*C8 -> 28091.18 | G8: =F8/$F$24 -> 0.026353127 | H8: =D8*C8 -> 26155.02 | I8: =F8-H8 -> 1936.16 | J8: =(I8/H8) -> 0.074026325 | K8: ='Active Portfolio'!C13 -> 169.99 | L8: =(E8-K8)/K8 -> -0.022177775 | M8: =IF(L8>=-0.03, "🚀 Breakout Watch", "") -> 🚀 Breakout Watch | N8: ='Active Portfolio'!D13 -> 140.68
A9: JPM | B9: Financials | C9: ='Transaction Sheet'!D30 -> 251 | D9: ='Transaction Sheet'!D31 -> 271.75514 | E9: ='Active Portfolio'!B6 -> 298.28 | F9: =E9*C9 -> 74868.28 | G9: =F9/$F$24 -> 0.070236043 | H9: =D9*C9 -> 68210.54 | I9: =F9-H9 -> 6657.74 | J9: =(I9/H9) -> 0.097605737 | K9: ='Active Portfolio'!C6 -> 299.5899 | L9: =(E9-K9)/K9 -> -0.0043723103 | M9: =IF(L9>=-0.03, "🚀 Breakout Watch", "") -> 🚀 Breakout Watch | N9: ='Active Portfolio'!D6 -> 190.9
A10: LNG | B10: Energy | C10: ='Transaction Sheet'!D101 -> 236 | D10: ='Transaction Sheet'!D102 -> 225.86051 | E10: ='Active Portfolio'!B17 -> 228.48 | F10: =E10*C10 -> 53921.28 | G10: =F10/$F$24 -> 0.050585072 | H10: =D10*C10 -> 53303.08 | I10: =F10-H10 -> 618.2 | J10: =(I10/H10) -> 0.011597829 | K10: ='Active Portfolio'!C17 -> 257.65 | L10: =(E10-K10)/K10 -> -0.1132156 | M10: =IF(L10>=-0.03, "🚀 Breakout Watch", "") | N10: ='Active Portfolio'!D17 -> 167.6632
A11: NFLX | B11: Communication Service | C11: ='Transaction Sheet'!D25 -> 49 | D11: ='Transaction Sheet'!D26 -> 1028.1033 | E11: ='Active Portfolio'!B3 -> 1174.6 | F11: =E11*C11 -> 57555.4 | G11: =F11/$F$24 -> 0.053994342 | H11: =D11*C11 -> 50377.06 | I11: =F11-H11 -> 7178.34 | J11: =(I11/H11) -> 0.14249224 | K11: ='Active Portfolio'!C3 -> 1341.15 | L11: =(E11-K11)/K11 -> -0.12418447 | M11: =IF(L11>=-0.03, "🚀 Breakout Watch", "") | N11: ='Active Portfolio'!D3 -> 587.04
A12: NUE | B12: Materials | C12: ='Transaction Sheet'!D111 -> 88 | D12: ='Transaction Sheet'!D112 -> 118.81239 | E12: ='Active Portfolio'!B8 -> 144.52 | F12: =E12*C12 -> 12717.76 | G12: =F12/$F$24 -> 0.011930889 | H12: =D12*C12 -> 10455.49 | I12: =F12-H12 -> 2262.27 | J12: =(I12/H12) -> 0.21637149 | K12: ='Active Portfolio'!C8 -> 170.52 | L12: =(E12-K12)/K12 -> -0.15247478 | M12: =IF(L12>=-0.03, "🚀 Breakout Watch", "") | N12: ='Active Portfolio'!D8 -> 97.59
A13: NVDA | B13: Technology | C13: ='Transaction Sheet'!D8 -> 267 | D13: ='Transaction Sheet'!D9 -> 118.81457 | E13: ='Active Portfolio'!B4 -> 176.75 | F13: =E13*C13 -> 47192.25 | G13: =F13/$F$24 -> 0.044272379 | H13: =D13*C13 -> 31723.49 | I13: =F13-H13 -> 15468.76 | J13: =(I13/H13) -> 0.48761218 | K13: ='Active Portfolio'!C4 -> 177 | L13: =(E13-K13)/K13 -> -0.0014124294 | M13: =IF(L13>=-0.03, "🚀 Breakout Watch", "") -> 🚀 Breakout Watch | N13: ='Active Portfolio'!C4 -> 177
A14: PYPL | B14: Financial Technology | C14: ='Transaction Sheet'!D106 -> 199 | D14: ='Transaction Sheet'!D107 -> 69.49598 | E14: ='Active Portfolio'!B18 -> 78.22 | F14: =E14*C14 -> 15565.78 | G14: =F14/$F$24 -> 0.014602697 | H14: =D14*C14 -> 13829.7 | I14: =F14-H14 -> 1736.08 | J14: =(I14/H14) -> 0.12553273 | K14: ='Active Portfolio'!C18 -> 93.66 | L14: =(E14-K14)/K14 -> -0.16485159 | M14: =IF(L14>=-0.03, "🚀 Breakout Watch", "") | N14: ='Active Portfolio'!D18 -> 55.85
A15: QQQ | B15: Tech Heavy ETF | C15: ='Transaction Sheet'!D77 -> 94 | D15: ='Transaction Sheet'!E74 -> 514.8 | E15: ='Active Portfolio'!B15 -> 568.14 | F15: =E15*C15 -> 53405.16 | G15: =F15/$F$24 -> 0.050100885 | H15: =D15*C15 -> 48391.2 | I15: =F15-H15 -> 5013.96 | J15: =(I15/H15) -> 0.10361305 | K15: ='Active Portfolio'!C15 -> 569.04 | L15: =(E15-K15)/K15 -> -0.0015816111 | M15: =IF(L15>=-0.03, "🚀 Breakout Watch", "") -> 🚀 Breakout Watch | N15: ='Active Portfolio'!D15 -> 402.39
A16: SPY | B16: Diversified ETF | C16: 31 | D16: ='Transaction Sheet'!E80 -> 588.14 | E16: ='Active Portfolio'!B14 -> 636.94 | F16: =E16*C16 -> 19745.14 | G16: =F16/$F$24 -> 0.018523472 | H16: =D16*C16 -> 18232.34 | I16: =F16-H16 -> 1512.8 | J16: =(I16/H16) -> 0.082973442 | K16: ='Active Portfolio'!C14 -> 638.04 | L16: =(E16-K16)/K16 -> -0.0017240298 | M16: =IF(L16>=-0.03, "🚀 Breakout Watch", "") -> 🚀 Breakout Watch | N16: ='Active Portfolio'!D14 -> 481.8
A17: VXUS | B17: International ETF | C17: ='Transaction Sheet'!D41 -> 1513 | D17: ='Transaction Sheet'!D42 -> 67.399888 | E17: ='Active Portfolio'!B7 -> 69.57 | F17: =E17*C17 -> 105259.41 | G17: =F17/$F$24 -> 0.098746818 | H17: =D17*C17 -> 101976.03 | I17: =F17-H17 -> 3283.38 | J17: =(I17/H17) -> 0.032197566 | K17: ='Active Portfolio'!C7 -> 71.08 | L17: =(E17-K17)/K17 -> -0.021243669 | M17: =IF(L17>=-0.03, "🚀 Breakout Watch", "") -> 🚀 Breakout Watch | N17: ='Active Portfolio'!D7 -> 54.98
A18: XOM | B18: Energy | C18: ='Transaction Sheet'!D48 -> 174 | D18: ='Transaction Sheet'!D49 -> 109.70448 | E18: ='Active Portfolio'!B9 -> 111.44 | F18: =E18*C18 -> 19390.56 | G18: =F18/$F$24 -> 0.018190831 | H18: =D18*C18 -> 19088.58 | I18: =F18-H18 -> 301.98 | J18: =(I18/H18) -> 0.01581993 | K18: ='Active Portfolio'!C9 -> 126.34 | L18: =(E18-K18)/K18 -> -0.11793573 | M18: =IF(L18>=-0.03, "🚀 Breakout Watch", "") | N18: ='Active Portfolio'!D19 -> 202.955
A19: VDC | B19: Consumer Staples | C19: ='Transaction Sheet'!D114 -> 190 | D19: ='Transaction Sheet'!E114 -> 216.99 | E19: ='Active Portfolio'!B19 -> 218.27 | F19: =E19*C19 -> 41471.3 | G19: =F19/$F$24 -> 0.038905395 | H19: =D19*C19 -> 41228.1 | I19: =F19-H19 -> 243.2 | J19: =(I19/H19) -> 0.0058988893 | K19: ='Active Portfolio'!C19 -> 226.64 | L19: =(E19-K19)/K19 -> -0.036930815 | M19: =IF(L19>=-0.03, "🚀 Breakout Watch", "")
A20: MA | B20: Financials | C20: ='Transaction Sheet'!D118 -> 20 | D20: ='Transaction Sheet'!E117 -> 557.82 | E20: ='Active Portfolio'!B20 -> 568.28 | F20: =E20*C20 -> 11365.6 | G20: =F20/$F$24 -> 0.01066239 | H20: =D20*C20 -> 11156.4 | I20: =F20-H20 -> 209.2 | J20: =(I20/H20) -> 0.018751569 | K20: ='Active Portfolio'!C20 -> 594.71 | L20: =(E20-K20)/K20 -> -0.044441829 | M20: =IF(L20>=-0.03, "🚀 Breakout Watch", "") | N20: ='Active Portfolio'!D20 -> 566.22
A21: V | B21: Financials | C21: ='Transaction Sheet'!D121 -> 32 | D21: ='Transaction Sheet'!E120 -> 353 | E21: ='Active Portfolio'!B21 -> 355.47 | F21: =E21*C21 -> 11375.04 | G21: =F21/$F$24 -> 0.010671246 | H21: =D21*C21 -> 11296 | I21: =F21-H21 -> 79.04 | J21: =(I21/H21) -> 0.0069971671 | K21: ='Active Portfolio'!C21 -> 375.51 | L21: =(E21-K21)/K21 -> -0.05336742 | M21: =IF(L21>=-0.03, "🚀 Breakout Watch", "") | N21: ='Active Portfolio'!D21 -> 254.51
A22: Cash Available | F22: ='Summary Dashboard'!B4 -> 363102.99 | I22: =SUM(Table2[Gain/Loss]) -> 66155.8
A23: Market Value | F23: =SUM(Table2[Market Value]) -> 754670.76
A24: Total Portfolio Value | F24: ='Summary Dashboard'!B3 -> 1065952.4

Sheet Transaction Sheet
A1: Company | B1: Date | C1: Ticker | D1: Shares Bought/Sell | E1: Price per Share | F1: Total Cost | G1: Remarks/Reminders
A2: Nvidia | B2: 45627 | C2: NVDA | D2: 100 | E2: 137.09 | F2: =D2*E2 -> 13709
A3: Nvidia | B3: 45628 | C3: NVDA | D3: 200 | E3: 136 | F3: =D3*E3 -> 27200
A4: Nvidia | B4: 45784 | C4: NVDA | D4: 100 | E4: 112.89 | F4: =D4*E4 -> 11289
A5: Nvidia | B5: 45795 | C5: NVDA | D5: -31 | E5: 132.69 | F5: =D5*E5 -> -4113.39
B6: 45836 | C6: NVDA | D6: -55 | E6: 157.94 | F6: =D6*E6-10 -> -8696.7
B7: 45847 | C7: NVDA | D7: -47 | E7: 162.86 | F7: =D7*E7-10 -> -7664.42
B8: Total Summary | D8: =SUM(D2:D7) -> 267 | F8: =SUM(F2:F7) -> 31723.49
B9: Total average cost per share | D9: =F8/D8 -> 118.81457
A11: Google | B11: 45670 | C11: GOOG | D11: 50 | E11: 190.56 | F11: =D11*E11 -> 9528
A12: Google | B12: 45784 | C12: GOOG | D12: 100 | E12: 166.49 | F12: =D12*E12 -> 16649
A13: Google | B13: 45791 | C13: GOOG | D13: 50 | E13: 166.81 | F13: =D13*E13 -> 8340.5
A14: Google | B14: 45798 | C14: GOOG | D14: 40 | E14: 172.9 | F14: =D14*E14 -> 6916
A15: Google | B15: 45804 | C15: GOOG | D15: 27 | E15: 173.21 | F15: =D15*E15 -> 4676.67
B16: 45855 | C16: GOOG | D16: 30 | E16: 184.7 | F16: =D16*E16 -> 5541
B17: Total Summary | D17: =SUM(D11:D16) -> 297 | F17: =SUM(F11:F16) -> 51651.17
B18: Total average cost per share | D18: =F17/D17 -> 173.90966
B19: NetFlix
A20: Netflix | B20: 45665 | C20: NFLX | D20: 25 | E20: 876.86 | F20: =E20*D20 -> 21921.5
A21: Netflix | B21: 45684 | C21: NFLX | D21: 8 | E21: 1203.24 | F21: =E21*D21 -> 9625.92
B22: 45815 | C22: NFLX | D22: 6 | E22: 1234.81 | F22: =E22*D22 -> 7408.86
B23: 45835 | C23: NFLX | D23: -6 | E23: 1322.51 | F23: =E23*D23 -> -7935.06
B24: 45856 | C24: NFLX | D24: 16 | E24: 1209.74 | F24: =E24*D24 -> 19355.84
B25: Total Summary | D25: =SUM(D20:D24) -> 49 | F25: =SUM(F20:F24) -> 50377.06
B26: Total average cost per share | D26: =F25/D25 -> 1028.1033
A28: JP Morgan | B28: 45792 | C28: JPM | D28: 187 | E28: 268.42 | F28: =D28*E28 -> 50194.54
B29: 45833 | C29: JPM | D29: 64 | E29: 281.5 | F29: =D29*E29 -> 18016
B30: Total Summary | D30: =SUM(D28:D29) -> 251 | F30: =SUM(F28:F29) -> 68210.54
B31: Total average cost per share | D31: =F30/D30 -> 271.75514
A33: Coca Cola | B33: 45792 | C33: KO | D33: 350 | E33: 71.61 | F33: =D33*E33 -> 25063.5
B34: 45834 | C34: KO | D34: -350 | E34: 69.31 | F34: =D34*E34 -> -24258.5
B35: Total Summary | D35: =SUM(D33:D34) -> 0 | F35: =SUM(F33:F34) -> 805
A37: Vanguard Int ETF | B37: 45792 | C37: VXUS | D37: 755 | E37: 66.21 | F37: =D37*E37 -> 49988.55
B38: 45795 | C38: VXUS | D38: -92 | E38: 66.16 | F38: =D38*E38 -> -6086.72
B39: 45815 | C39: VXUS | D39: 630 | E39: 68.1 | F39: =D39*E39 -> 42903
B40: 45842 | C40: VXUS | D40: 220 | E40: 68.96 | F40: =D40*E40 -> 15171.2
B41: Total Summary | D41: =SUM(D37:D40) -> 1513 | F41: =SUM(F37:F40) -> 101976.03
B42: Total average cost per share | D42: =F41/D41 -> 67.399888
A44: Exxon | B44: 45795 | C44: XOM | D44: 29 | E44: 107.56 | F44: =D44*E44 -> 3119.24
B45: 45822 | C45: XOM | D45: 100 | E45: 112.04 | F45: =D45*E45 -> 11204
...

Sheet Stop Loss & Price Alert
A1: Ticker | B1: Current Price | C1: Entry Price | D1: Highest Price | E1: Trailing Stop Price | F1: Stop Status | G1: % to Stop | H1: Near Stop Alert | I1: Comments | J1: Target Price | K1: % to Target | L1: Target Status | M1: Last Review Date | N1: Comments2
A2: NVDIA | B2: ='Active Portfolio'!B4 -> 176.75 | C2: ='Holdings Sheet'!D13 -> 118.81457 | D2: =B2 -> 176.75 | E2: =D2*0.9545 -> 168.70788 | F2: =IF(B2<=E2, "Triggered Stop Loss", "✅ Active") -> ✅ Active | G2: =(B2-E2)/B2 -> 0.0455 | H2: =IF(G2<=3%,"Near Stop Zone", " ") | J2: =ROUND(Table4[[#This Row],[Entry Price]] * 1.4, 2) -> 166.34 | K2: =ROUND((Table4[[#This Row],[Target Price]]-Table4[[#This Row],[Current Price]])/Table4[[#This Row],[Current Price]],2) -> -0.06 | L2: =IF(Table4[[#This Row],[Current Price]]>=Table4[[#This Row],[Target Price]],"🎯 Trim Alert", "✅ Hold") -> 🎯 Trim Alert | M2: 45843 | N2: Target met 7/5 to
A3: NUE | B3: ='Active Portfolio'!B8 -> 144.52 | C3: ='Holdings Sheet'!D12 -> 118.81239 | D3: =B3 -> 144.52 | E3: =D3*0.915 -> 132.2358 | F3: =IF(B3<=E3, "Triggered Stock Option", "✅ Active") -> ✅ Active | G3: =(B3-E3)/B3 -> 0.085 | H3: =IF(G3<=3%,"Near Stop Zone", " ") | J3: =ROUND(Table4[[#This Row],[Entry Price]] * 1.3, 2) -> 154.46 | K3: =ROUND((Table4[[#This Row],[Target Price]]-Table4[[#This Row],[Current Price]])/Table4[[#This Row],[Current Price]],2) -> 0.07 | L3: =IF(Table4[[#This Row],[Current Price]]>=Table4[[#This Row],[Target Price]],"🎯 Trim Alert", "✅ Hold") -> ✅ Hold | M3: 45843
A4: FSLR | B4: ='Active Portfolio'!B16 -> 183.58 | C4: ='Holdings Sheet'!D6 -> 153.1958 | D4: =B4 -> 183.58 | E4: =D4*0.925 -> 169.8115 | F4: =IF(B4<=E4, "Triggered Stock Option", "✅ Active") -> ✅ Active | G4: =(B4-E4)/B4 -> 0.075 | H4: =IF(G4<=3%,"Near Stop Zone", " ") | J4: =ROUND(Table4[[#This Row],[Entry Price]] * 1.3, 2) -> 199.15 | K4: =ROUND((Table4[[#This Row],[Target Price]]-Table4[[#This Row],[Current Price]])/Table4[[#This Row],[Current Price]],2) -> 0.08 | L4: =IF(Table4[[#This Row],[Current Price]]>=Table4[[#This Row],[Target Price]],"🎯 Trim Alert", "✅ Hold") -> ✅ Hold | M4: 45843
A5: PYPL | B5: ='Active Portfolio'!B18 -> 78.22 | C5: ='Holdings Sheet'!D14 -> 69.49598 | D5: =B5 -> 78.22 | E5: =D5*0.96 -> 75.0912 | F5: =IF(B5<=E5, "Triggered Stop Loss", "✅ Active") -> ✅ Active | G5: =(B5-E5)/B5 -> 0.04 | H5: =IF(G5<=3%,"Near Stop Zone", " ") | J5: =ROUND(Table4[[#This Row],[Entry Price]] * 1.3, 2) -> 90.34 | K5: =ROUND((Table4[[#This Row],[Target Price]]-Table4[[#This Row],[Current Price]])/Table4[[#This Row],[Current Price]],2) -> 0.15 | L5: =IF(Table4[[#This Row],[Current Price]]>=Table4[[#This Row],[Target Price]],"🎯 Trim Alert", "✅ Hold") -> ✅ Hold | M5: 45843
A6: GOOG | B6: ='Active Portfolio'!B5 -> 193.42 | C6: ='Holdings Sheet'!D7 -> 173.90966 | D6: =B6 -> 193.42 | E6: =D6*0.92 -> 177.9464 | F6: =IF(B6<=E6,"Triggered Stock Option", "✅ Active") -> ✅ Active | G6: =(B6-E6)/B6 -> 0.08 | H6: =IF(G6<=3%,"Near Stop Zone", " ") | J6: =ROUND(Table4[[#This Row],[Entry Price]] * 1.3, 2) -> 226.08 | K6: =ROUND((Table4[[#This Row],[Target Price]]-Table4[[#This Row],[Current Price]])/Table4[[#This Row],[Current Price]],2) -> 0.17 | L6: =IF(Table4[[#This Row],[Current Price]]>=Table4[[#This Row],[Target Price]],"🎯 Trim Alert", "✅ Hold") -> ✅ Hold | M6: 45848
A7: QQQ | B7: ='Active Portfolio'!B15 -> 568.14 | C7: ='Holdings Sheet'!D15 -> 514.8 | D7: =B7 -> 568.14 | E7: =D7*0.95 -> 539.733 | F7: =IF(B7<=E7, "Triggered Stop Loss", "✅ Active") -> ✅ Active | G7: =(B7-E7)/B7 -> 0.05 | H7: =IF(G7<=3%,"Near Stop Zone", " ") | J7: =ROUND(Table4[[#This Row],[Entry Price]] * 1.3, 2) -> 669.24 | K7: =ROUND((Table4[[#This Row],[Target Price]]-Table4[[#This Row],[Current Price]])/Table4[[#This Row],[Current Price]],2) -> 0.18 | L7: =IF(Table4[[#This Row],[Current Price]]>=Table4[[#This Row],[Target Price]],"🎯 Trim Alert", "✅ Hold") -> ✅ Hold | M7: 45843
A8: JPM | B8: ='Active Portfolio'!B6 -> 298.28 | C8: ='Holdings Sheet'!D9 -> 271.75514 | D8: =B8 -> 298.28 | E8: =D8*0.939 -> 280.08492 | F8: =IF(B8<=E8, "Triggered Stop Loss", "✅ Active") -> ✅ Active | G8: =(B8-E8)/B8 -> 0.061 | H8: =IF(G8<=3%,"Near Stop Zone", " ") | J8: =ROUND(Table4[[#This Row],[Entry Price]] * 1.3, 2) -> 353.28 | K8: =ROUND((Table4[[#This Row],[Target Price]]-Table4[[#This Row],[Current Price]])/Table4[[#This Row],[Current Price]],2) -> 0.18 | L8: =IF(Table4[[#This Row],[Current Price]]>=Table4[[#This Row],[Target Price]],"🎯 Trim Alert", "✅ Hold") -> ✅ Hold | M8: 45843
A9: CAT | B9: ='Active Portfolio'!B10 -> 432.94 | C9: ='Holdings Sheet'!D5 -> 391.83646 | D9: =B9 -> 432.94 | E9: =D9*0.971 -> 420.38474 | F9: =IF(B9<=E9, "Triggered Stop Loss", "✅ Active") -> ✅ Active | G9: =(B9-E9)/B9 -> 0.029 | H9: =IF(G9<=3%,"Near Stop Zone", " ") -> Near Stop Zone | J9: =ROUND(Table4[[#This Row],[Entry Price]] * 1.3, 2) -> 509.39 | K9: =ROUND((Table4[[#This Row],[Target Price]]-Table4[[#This Row],[Current Price]])/Table4[[#This Row],[Current Price]],2) -> 0.18 | L9: =IF(Table4[[#This Row],[Current Price]]>=Table4[[#This Row],[Target Price]],"🎯 Trim Alert", "✅ Hold") -> ✅ Hold | M9: 45843
A10: JNJ | B10: ='Active Portfolio'!B13 -> 166.22 | C10: ='Holdings Sheet'!D8 -> 154.76343 | D10: 155.21 | E10: =D10*0.985 -> 152.88185 | F10: =IF(B10<=E10,"Triggered Stock Option", "✅ Active") -> ✅ Active | G10: =(B10-E10)/B10 -> 0.080243954 | H10: =IF(G10<=3%,"Near Stop Zone", " ") | J10: =ROUND(Table4[[#This Row],[Entry Price]] * 1.3, 2) -> 201.19 | K10: =ROUND((Table4[[#This Row],[Target Price]]-Table4[[#This Row],[Current Price]])/Table4[[#This Row],[Current Price]],2) -> 0.21 | L10: =IF(Table4[[#This Row],[Current Price]]>=Table4[[#This Row],[Target Price]],"🎯 Trim Alert", "✅ Hold") -> ✅ Hold | M10: 45843
A11: SPY | B11: ='Active Portfolio'!B14 -> 636.94 | C11: ='Holdings Sheet'!D16 -> 588.14 | D11: =B11 -> 636.94 | E11: =D11*0.9577 -> 609.99744 | F11: =IF(B11<=E11, "Triggered Stop Loss", "✅ Active") -> ✅ Active | G11: =(B11-E11)/B11 -> 0.0423 | H11: =IF(G11<=3%,"Near Stop Zone", " ") | J11: =ROUND(Table4[[#This Row],[Entry Price]] * 1.3, 2) -> 764.58 | K11: =ROUND((Table4[[#This Row],[Target Price]]-Table4[[#This Row],[Current Price]])/Table4[[#This Row],[Current Price]],2) -> 0.2 | L11: =IF(Table4[[#This Row],[Current Price]]>=Table4[[#This Row],[Target Price]],"🎯 Trim Alert", "✅ Hold") -> ✅ Hold | M11: 45843
A12: VXUS | B12: ='Active Portfolio'!B7 -> 69.57 | C12: ='Holdings Sheet'!D17 -> 67.399888 | D12: =B12 -> 69.57 | E12: =D12*0.95 -> 66.0915 | F12: =IF(B12<=E12, "Triggered Stock Option", "✅ Active") -> ✅ Active | G12: =(B11-E11)/B11 -> 0.0423 | H12: =IF(G12<=3%,"Near Stop Zone", " ") | J12: =ROUND(Table4[[#This Row],[Entry Price]] * 1.3, 2) -> 87.62 | K12: =ROUND((Table4[[#This Row],[Target Price]]-Table4[[#This Row],[Current Price]])/Table4[[#This Row],[Current Price]],2) -> 0.26 | L12: =IF(Table4[[#This Row],[Current Price]]>=Table4[[#This Row],[Target Price]],"🎯 Trim Alert", "✅ Hold") -> ✅ Hold | M12: 45843
A13: AMZN | B13: ='Active Portfolio'!B11 -> 232.79 | C13: ='Holdings Sheet'!D4 -> 217.51404 | D13: =B13 -> 232.79 | E13: =D13*0.96 -> 223.4784 | F13: =IF(B13<=E13, "Triggered Stock Option", "✅ Active") -> ✅ Active | G13: =(B13-E13)/B13 -> 0.04 | H13: =IF(G13<=3%,"Near Stop Zone", " ") | J13: =ROUND(Table4[[#This Row],[Entry Price]] * 1.3, 2) -> 282.77 | K13: =ROUND((Table4[[#This Row],[Target Price]]-Table4[[#This Row],[Current Price]])/Table4[[#This Row],[Current Price]],2) -> 0.21 | L13: =IF(Table4[[#This Row],[Current Price]]>=Table4[[#This Row],[Target Price]],"🎯 Trim Alert", "✅ Hold") -> ✅ Hold | M13: 45843
A14: NFLX | B14: ='Active Portfolio'!B3 -> 1174.6 | C14: ='Holdings Sheet'!D11 -> 1028.1033 | D14: ='Active Portfolio'!B3 -> 1174.6 | E14: =D14*0.93 -> 1092.378 | F14: =IF(B14<=E14, "Triggered Stock Option", "✅ Active") -> ✅ Active | G14: =(B14-E14)/B14 -> 0.07 | H14: =IF(G14<=3%,"Near Stop Zone", " ") | I14: Complete Stop Loss 7/7/25 | J14: =ROUND(Table4[[#This Row],[Entry Price]] * 1.47, 2) -> 1511.31 | K14: =ROUND((Table4[[#This Row],[Target Price]]-Table4[[#This Row],[Current Price]])/Table4[[#This Row],[Current Price]],2) -> 0.29 | L14: =IF(Table4[[#This Row],[Current Price]]>=Table4[[#This Row],[Target Price]],"🎯 Trim Alert", "✅ Hold") -> ✅ Hold | M14: 45843
A15: VDC | B15: ='Active Portfolio'!B19 -> 218.27 | C15: ='Holdings Sheet'!D19 -> 216.99 | D15: =B15 -> 218.27 | E15: =D15*0.96 -> 209.5392 | F15: =IF(B15<=E15, "Triggered Stop Loss", "✅ Active") -> ✅ Active | G15: =(B15-E15)/B15 -> 0.04 | H15: =IF(G15<=3%,"Near Stop Zone", " ") | J15: =ROUND(Table4[[#This Row],[Entry Price]] * 1.3, 2) -> 282.09 | K15: =ROUND((Table4[[#This Row],[Target Price]]-Table4[[#This Row],[Current Price]])/Table4[[#This Row],[Current Price]],2) -> 0.29 | L15: =IF(Table4[[#This Row],[Current Price]]>=Table4[[#This Row],[Target Price]],"🎯 Trim Alert", "✅ Hold") -> ✅ Hold | M15: 45843
A16: MA | B16: ='Active Portfolio'!B20 -> 568.28 | C16: ='Holdings Sheet'!D20 -> 557.82 | D16: =B16 -> 568.28 | E16: =D16*0.9285 -> 527.64798 | F16: =IF(B16<=E16,"Triggered Stock Option", "✅ Active") -> ✅ Active | G16: =(B16-E16)/B16 -> 0.0715 | H16: =IF(G16<=3%,"Near Stop Zone", " ") | J16: =ROUND(Table4[[#This Row],[Entry Price]] * 1.3, 2) -> 725.17 | K16: =ROUND((Table4[[#This Row],[Target Price]]-Table4[[#This Row],[Current Price]])/Table4[[#This Row],[Current Price]],2) -> 0.28 | L16: =IF(Table4[[#This Row],[Current Price]]>=Table4[[#This Row],[Target Price]],"🎯 Trim Alert", "✅ Hold") -> ✅ Hold | M16: 7212025
A17: V | B17: ='Active Portfolio'!B21 -> 355.47 | C17: ='Holdings Sheet'!D21 -> 353 | D17: =B17 -> 355.47 | E17: =D17*0.9285 -> 330.0539 | F17: =IF(B17<=E17,"Triggered Stock Option", "✅ Active") -> ✅ Active | G17: =(B17-E17)/B17 -> 0.0715 | H17: =IF(G17<=3%,"Near Stop Zone", " ") | J17: =ROUND(Table4[[#This Row],[Entry Price]] * 1.3, 2) -> 458.9 | K17: =ROUND((Table4[[#This Row],[Target Price]]-Table4[[#This Row],[Current Price]])/Table4[[#This Row],[Current Price]],2) -> 0.29 | L17: =IF(Table4[[#This Row],[Current Price]]>=Table4[[#This Row],[Target Price]],"🎯 Trim Alert", "✅ Hold") -> ✅ Hold | M17: 7212025
A18: XOM | B18: ='Active Portfolio'!B9 -> 111.44 | C18: ='Holdings Sheet'!D18 -> 109.70448 | D18: =B18 -> 111.44 | E18: =D18*0.957 -> 106.64808 | F18: =IF(B18<=E18, "Triggered Stock Option", "✅ Active") -> ✅ Active | G18: =(B18-E18)/B18 -> 0.043 | H18: =IF(G18<=3%,"Near Stop Zone", " ") | J18: =ROUND(Table4[[#This Row],[Entry Price]] * 1.3, 2) -> 142.62 | K18: =ROUND((Table4[[#This Row],[Target Price]]-Table4[[#This Row],[Current Price]])/Table4[[#This Row],[Current Price]],2) -> 0.28 | L18: =IF(Table4[[#This Row],[Current Price]]>=Table4[[#This Row],[Target Price]],"🎯 Trim Alert", "✅ Hold") -> ✅ Hold | M18: 45843
A19: LNG | B19: ='Active Portfolio'!B17 -> 228.48 | C19: ='Holdings Sheet'!D10 -> 225.86051 | D19: =B19 -> 228.48 | E19: =D19*0.95 -> 217.056 | F19: =IF(B19<=E19, "Triggered Stop Loss", "✅ Active") -> ✅ Active | G19: =(B19-E19)/B19 -> 0.05 | H19: =IF(G19<=3%,"Near Stop Zone", " ") | I19: Stop loss 7/6/2025 | J19: =ROUND(Table4[[#This Row],[Entry Price]] * 1.3, 2) -> 293.62 | K19: =ROUND((Table4[[#This Row],[Target Price]]-Table4[[#This Row],[Current Price]])/Table4[[#This Row],[Current Price]],2) -> 0.29 | L19: =IF(Table4[[#This Row],[Current Price]]>=Table4[[#This Row],[Target Price]],"🎯 Trim Alert", "✅ Hold") -> ✅ Hold | M19: 45843

Sheet Sectors Numbers
D1: Market | E1: Market | F1: Total | G1: Gains & | H1: % | I1: Sector &
A2: Sector | B2: Market Value | D2: Sector | E2: Value | F2: Cost | G2: Losses | H2: Return | I2: Return
A3: =Table2[[#This Row],[Sector]] -> Technology | B3: ='Holdings Sheet'!F3 -> 31465.35 | D3: Communication Service | E3: =SUMIF($A$3:$A$19, D3, $B$3:$B$19) -> 57555.4 | F3: =SUMIFS('Holdings Sheet'!$H$3:$H$21, 'Holdings Sheet'!$B$3:$B$21, D3) -> 50377.06 | G3: =E3-F3 -> 7178.34 | H3: =(E3-F3)/F3 -> 0.14249224 | I3: =D3 & CHAR(10) & TEXT(H3,"0.0%") -> Communication Service 14.2%
A4: =Table2[[#This Row],[Sector]] -> Technology | B4: =Table2[[#This Row],[Market Value]] -> 32823.39 | D4: Technology | E4: =SUMIF($A$3:$A$19, D4, $B$3:$B$19) -> 168926.73 | F4: =SUMIFS('Holdings Sheet'!$H$3:$H$21, 'Holdings Sheet'!$B$3:$B$21, D4) -> 145225.66 | G4: =E4-F4 -> 23701.07 | H4: =(E4-F4)/F4 -> 0.16320167 | I4: =D4 & CHAR(10) & TEXT(H4,"0.0%") -> Technology 16.3%
A5: =Table2[[#This Row],[Sector]] -> Industrials | B5: =Table2[[#This Row],[Market Value]] -> 28141.1 | D5: Financial Technology | E5: =SUMIF($A$3:$A$19, D5, $B$3:$B$19) -> 15565.78 | F5: =SUMIFS('Holdings Sheet'!$H$3:$H$21, 'Holdings Sheet'!$B$3:$B$21, D5) -> 13829.7 | G5: =E5-F5 -> 1736.08 | H5: =(E5-F5)/F5 -> 0.12553273 | I5: =D5 & CHAR(10) & TEXT(H5,"0.0%") -> Financial Technology 12.6%
A6: =Table2[[#This Row],[Sector]] -> Industrials | B6: =Table2[[#This Row],[Market Value]] -> 52871.04 | D6: Industrials | E6: =SUMIF($A$3:$A$19, D6, $B$3:$B$19) -> 81012.14 | F6: =SUMIFS('Holdings Sheet'!$H$3:$H$21, 'Holdings Sheet'!$B$3:$B$21, D6) -> 69589.76 | G6: =E6-F6 -> 11422.38 | H6: =(E6-F6)/F6 -> 0.1641388 | I6: =D6 & CHAR(10) & TEXT(H6,"0.0%") -> Industrials 16.4%
A7: =Table2[[#This Row],[Sector]] -> Technology | B7: =Table2[[#This Row],[Market Value]] -> 57445.74 | D7: International ETF | E7: =SUMIF($A$3:$A$19, D7, $B$3:$B$19) -> 105259.41 | F7: =SUMIFS('Holdings Sheet'!$H$3:$H$21, 'Holdings Sheet'!$B$3:$B$21, D7) -> 101976.03 | G7: =E7-F7 -> 3283.38 | H7: =(E7-F7)/F7 -> 0.032197566 | I7: =D7 & CHAR(10) & TEXT(H7,"0.0%") -> International ETF 3.2%
A8: =Table2[[#This Row],[Sector]] -> Health Care | B8: =Table2[[#This Row],[Market Value]] -> 28091.18 | D8: Health Care | E8: =SUMIF($A$3:$A$19, D8, $B$3:$B$19) -> 28091.18 | F8: =SUMIFS('Holdings Sheet'!$H$3:$H$21, 'Holdings Sheet'!$B$3:$B$21, D8) -> 26155.02 | G8: =E8-F8 -> 1936.16 | H8: =(E8-F8)/F8 -> 0.074026325 | I8: =D8 & CHAR(10) & TEXT(H8,"0.0%") -> Health Care 7.4%
A9: =Table2[[#This Row],[Sector]] -> Financials | B9: =Table2[[#This Row],[Market Value]] -> 74868.28 | D9: Financials | E9: =SUMIF($A$3:$A$21, D9, $B$3:$B$21) -> 97608.92 | F9: =SUMIFS('Holdings Sheet'!$H$3:$H$21, 'Holdings Sheet'!$B$3:$B$21, D9) -> 90662.94 | G9: =E9-F9 -> 6945.98 | H9: =(E9-F9)/F9 -> 0.076613223 | I9: =D9 & CHAR(10) & TEXT(H9,"0.0%") -> Financials 7.7%
A10: =Table2[[#This Row],[Sector]] -> Energy | B10: =Table2[[#This Row],[Market Value]] -> 53921.28 | D10: Energy | E10: =SUMIF($A$3:$A$19, D10, $B$3:$B$19) -> 73311.84 | F10: =SUMIFS('Holdings Sheet'!$H$3:$H$21, 'Holdings Sheet'!$B$3:$B$21, D10) -> 72391.66 | G10: =E10-F10 -> 920.18 | H10: =IF(F10=0,0,(E10-F10)/F10) -> 0.012711133 | I10: =D10 & CHAR(10) & TEXT(H10,"0.0%") -> Energy 1.3%
A11: =Table2[[#This Row],[Sector]] -> Communication Service | B11: =Table2[[#This Row],[Market Value]] -> 57555.4 | D11: Consumer Staples | E11: =SUMIF($A$3:$A$19, D11, $B$3:$B$19) -> 41471.3 | F11: =SUMIFS('Holdings Sheet'!$H$3:$H$21, 'Holdings Sheet'!$B$3:$B$21, D11) -> 41228.1 | G11: =E11-F11 -> 243.2 | H11: =(E11-F11)/F11 -> 0.0058988893 | I11: =D11 & CHAR(10) & TEXT(H11,"0.0%") -> Consumer Staples 0.6%
A12: =Table2[[#This Row],[Sector]] -> Materials | B12: =Table2[[#This Row],[Market Value]] -> 12717.76 | D12: =A15 -> Tech Heavy ETF | E12: =SUMIF($A$3:$A$19, D12, $B$3:$B$19) -> 53405.16 | F12: =SUMIFS('Holdings Sheet'!$H$3:$H$21, 'Holdings Sheet'!$B$3:$B$21, D12) -> 48391.2 | G12: =E12-F12 -> 5013.96 | H12: =(E12-F12)/F12 -> 0.10361305 | I12: =D12 & CHAR(10) & TEXT(H12, "0.00%") -> Tech Heavy ETF 10.36%
A13: =Table2[[#This Row],[Sector]] -> Technology | B13: =Table2[[#This Row],[Market Value]] -> 47192.25 | D13: =A16 -> Diversified ETF | E13: =SUMIF($A$3:$A$19, D13, $B$3:$B$19) -> 19745.14 | F13: =SUMIFS('Holdings Sheet'!$H$3:$H$21, 'Holdings Sheet'!$B$3:$B$21, D13) -> 18232.34 | G13: =E13-F13 -> 1512.8 | H13: =(E13-F13)/F13 -> 0.082973442 | I13: =D13 & CHAR(10) & TEXT(H13, "0.00%") -> Diversified ETF 8.30%
A14: =Table2[[#This Row],[Sector]] -> Financial Technology | B14: =Table2[[#This Row],[Market Value]] -> 15565.78
A15: =Table2[[#This Row],[Sector]] -> Tech Heavy ETF | B15: =Table2[[#This Row],[Market Value]] -> 53405.16
A16: =Table2[[#This Row],[Sector]] -> Diversified ETF | B16: =Table2[[#This Row],[Market Value]] -> 19745.14
A17: =Table2[[#This Row],[Sector]] -> International ETF | B17: =Table2[[#This Row],[Market Value]] -> 105259.41
A18: =Table2[[#This Row],[Sector]] -> Energy | B18: =Table2[[#This Row],[Market Value]] -> 19390.56
A19: =Table2[[#This Row],[Sector]] -> Consumer Staples | B19: =Table2[[#This Row],[Market Value]] -> 41471.3
A20: =Table2[[#This Row],[Sector]] -> Financials | B20: =Table2[[#This Row],[Market Value]] -> 11365.6
A21: =Table2[[#This Row],[Sector]] -> Financials | B21: =Table2[[#This Row],[Market Value]] -> 11375.04

Sheet Sheet1
